Exception on /api/getTrafficSummary [GET]
Traceback (most recent call last):
  File "C:\Users\Kotresh\AppData\Local\Programs\Python\Python36\lib\site-packages\flask\app.py", line 2292, in wsgi_app
    response = self.full_dispatch_request()
  File "C:\Users\Kotresh\AppData\Local\Programs\Python\Python36\lib\site-packages\flask\app.py", line 1815, in full_dispatch_request
    rv = self.handle_user_exception(e)
  File "C:\Users\Kotresh\AppData\Local\Programs\Python\Python36\lib\site-packages\flask_cors\extension.py", line 161, in wrapped_function
    return cors_after_request(app.make_response(f(*args, **kwargs)))
  File "C:\Users\Kotresh\AppData\Local\Programs\Python\Python36\lib\site-packages\flask\app.py", line 1718, in handle_user_exception
    reraise(exc_type, exc_value, tb)
  File "C:\Users\Kotresh\AppData\Local\Programs\Python\Python36\lib\site-packages\flask\_compat.py", line 35, in reraise
    raise value
  File "C:\Users\Kotresh\AppData\Local\Programs\Python\Python36\lib\site-packages\flask\app.py", line 1813, in full_dispatch_request
    rv = self.dispatch_request()
  File "C:\Users\Kotresh\AppData\Local\Programs\Python\Python36\lib\site-packages\flask\app.py", line 1799, in dispatch_request
    return self.view_functions[rule.endpoint](**req.view_args)
  File "api.py", line 63, in getTrafficSummary
    return Convert_CSV_to_Dictionary.csv_to_dictionary('astha/Combined.csv')
NameError: name 'Convert_CSV_to_Dictionary' is not defined
Exception on /api/getTrafficSummary [GET]
Traceback (most recent call last):
  File "C:\Users\Kotresh\AppData\Local\Programs\Python\Python36\lib\site-packages\flask\app.py", line 1974, in make_response
    rv = self.response_class.force_type(rv, request.environ)
  File "C:\Users\Kotresh\AppData\Local\Programs\Python\Python36\lib\site-packages\werkzeug\wrappers.py", line 921, in force_type
    response = BaseResponse(*_run_wsgi_app(response, environ))
  File "C:\Users\Kotresh\AppData\Local\Programs\Python\Python36\lib\site-packages\werkzeug\wrappers.py", line 59, in _run_wsgi_app
    return _run_wsgi_app(*args)
  File "C:\Users\Kotresh\AppData\Local\Programs\Python\Python36\lib\site-packages\werkzeug\test.py", line 923, in run_wsgi_app
    app_rv = app(environ, start_response)
TypeError: 'dict' object is not callable

During handling of the above exception, another exception occurred:

Traceback (most recent call last):
  File "C:\Users\Kotresh\AppData\Local\Programs\Python\Python36\lib\site-packages\flask\app.py", line 2292, in wsgi_app
    response = self.full_dispatch_request()
  File "C:\Users\Kotresh\AppData\Local\Programs\Python\Python36\lib\site-packages\flask\app.py", line 1816, in full_dispatch_request
    return self.finalize_request(rv)
  File "C:\Users\Kotresh\AppData\Local\Programs\Python\Python36\lib\site-packages\flask\app.py", line 1831, in finalize_request
    response = self.make_response(rv)
  File "C:\Users\Kotresh\AppData\Local\Programs\Python\Python36\lib\site-packages\flask\app.py", line 1982, in make_response
    reraise(TypeError, new_error, sys.exc_info()[2])
  File "C:\Users\Kotresh\AppData\Local\Programs\Python\Python36\lib\site-packages\flask\_compat.py", line 34, in reraise
    raise value.with_traceback(tb)
  File "C:\Users\Kotresh\AppData\Local\Programs\Python\Python36\lib\site-packages\flask\app.py", line 1974, in make_response
    rv = self.response_class.force_type(rv, request.environ)
  File "C:\Users\Kotresh\AppData\Local\Programs\Python\Python36\lib\site-packages\werkzeug\wrappers.py", line 921, in force_type
    response = BaseResponse(*_run_wsgi_app(response, environ))
  File "C:\Users\Kotresh\AppData\Local\Programs\Python\Python36\lib\site-packages\werkzeug\wrappers.py", line 59, in _run_wsgi_app
    return _run_wsgi_app(*args)
  File "C:\Users\Kotresh\AppData\Local\Programs\Python\Python36\lib\site-packages\werkzeug\test.py", line 923, in run_wsgi_app
    app_rv = app(environ, start_response)
TypeError: 'dict' object is not callable
The view function did not return a valid response. The return type must be a string, tuple, Response instance, or WSGI callable, but it was a dict.
Exception on /api/getTrafficSummary [GET]
Traceback (most recent call last):
  File "C:\Users\Kotresh\AppData\Local\Programs\Python\Python36\lib\site-packages\flask\app.py", line 2292, in wsgi_app
    response = self.full_dispatch_request()
  File "C:\Users\Kotresh\AppData\Local\Programs\Python\Python36\lib\site-packages\flask\app.py", line 1815, in full_dispatch_request
    rv = self.handle_user_exception(e)
  File "C:\Users\Kotresh\AppData\Local\Programs\Python\Python36\lib\site-packages\flask_cors\extension.py", line 161, in wrapped_function
    return cors_after_request(app.make_response(f(*args, **kwargs)))
  File "C:\Users\Kotresh\AppData\Local\Programs\Python\Python36\lib\site-packages\flask\app.py", line 1718, in handle_user_exception
    reraise(exc_type, exc_value, tb)
  File "C:\Users\Kotresh\AppData\Local\Programs\Python\Python36\lib\site-packages\flask\_compat.py", line 35, in reraise
    raise value
  File "C:\Users\Kotresh\AppData\Local\Programs\Python\Python36\lib\site-packages\flask\app.py", line 1813, in full_dispatch_request
    rv = self.dispatch_request()
  File "C:\Users\Kotresh\AppData\Local\Programs\Python\Python36\lib\site-packages\flask\app.py", line 1799, in dispatch_request
    return self.view_functions[rule.endpoint](**req.view_args)
  File "api.py", line 62, in getTrafficSummary
    print(json.dumps(resp, allow_nan=False))
  File "C:\Users\Kotresh\AppData\Local\Programs\Python\Python36\lib\json\__init__.py", line 238, in dumps
    **kw).encode(obj)
  File "C:\Users\Kotresh\AppData\Local\Programs\Python\Python36\lib\json\encoder.py", line 199, in encode
    chunks = self.iterencode(o, _one_shot=True)
  File "C:\Users\Kotresh\AppData\Local\Programs\Python\Python36\lib\json\encoder.py", line 257, in iterencode
    return _iterencode(o, 0)
ValueError: Out of range float values are not JSON compliant
Exception on /api/checkCounterfeit [GET]
Traceback (most recent call last):
  File "C:\Users\Kotresh\AppData\Local\Programs\Python\Python36\lib\site-packages\flask\app.py", line 2292, in wsgi_app
    response = self.full_dispatch_request()
  File "C:\Users\Kotresh\AppData\Local\Programs\Python\Python36\lib\site-packages\flask\app.py", line 1815, in full_dispatch_request
    rv = self.handle_user_exception(e)
  File "C:\Users\Kotresh\AppData\Local\Programs\Python\Python36\lib\site-packages\flask_cors\extension.py", line 161, in wrapped_function
    return cors_after_request(app.make_response(f(*args, **kwargs)))
  File "C:\Users\Kotresh\AppData\Local\Programs\Python\Python36\lib\site-packages\flask\app.py", line 1718, in handle_user_exception
    reraise(exc_type, exc_value, tb)
  File "C:\Users\Kotresh\AppData\Local\Programs\Python\Python36\lib\site-packages\flask\_compat.py", line 35, in reraise
    raise value
  File "C:\Users\Kotresh\AppData\Local\Programs\Python\Python36\lib\site-packages\flask\app.py", line 1813, in full_dispatch_request
    rv = self.dispatch_request()
  File "C:\Users\Kotresh\AppData\Local\Programs\Python\Python36\lib\site-packages\flask\app.py", line 1799, in dispatch_request
    return self.view_functions[rule.endpoint](**req.view_args)
  File "api.py", line 74, in checkCounterfeit
    resp = {a:1, b:2}
NameError: name 'a' is not defined
Exception on /api/checkCounterfeit [GET]
Traceback (most recent call last):
  File "C:\Users\Kotresh\AppData\Local\Programs\Python\Python36\lib\site-packages\flask\app.py", line 2292, in wsgi_app
    response = self.full_dispatch_request()
  File "C:\Users\Kotresh\AppData\Local\Programs\Python\Python36\lib\site-packages\flask\app.py", line 1815, in full_dispatch_request
    rv = self.handle_user_exception(e)
  File "C:\Users\Kotresh\AppData\Local\Programs\Python\Python36\lib\site-packages\flask_cors\extension.py", line 161, in wrapped_function
    return cors_after_request(app.make_response(f(*args, **kwargs)))
  File "C:\Users\Kotresh\AppData\Local\Programs\Python\Python36\lib\site-packages\flask\app.py", line 1718, in handle_user_exception
    reraise(exc_type, exc_value, tb)
  File "C:\Users\Kotresh\AppData\Local\Programs\Python\Python36\lib\site-packages\flask\_compat.py", line 35, in reraise
    raise value
  File "C:\Users\Kotresh\AppData\Local\Programs\Python\Python36\lib\site-packages\flask\app.py", line 1813, in full_dispatch_request
    rv = self.dispatch_request()
  File "C:\Users\Kotresh\AppData\Local\Programs\Python\Python36\lib\site-packages\flask\app.py", line 1799, in dispatch_request
    return self.view_functions[rule.endpoint](**req.view_args)
  File "api.py", line 77, in checkCounterfeit
    f = open(filepath,)
FileNotFoundError: [Errno 2] No such file or directory: '/results/checkCounterfeit/HS_1'
Exception on /api/checkCounterfeit [GET]
Traceback (most recent call last):
  File "C:\Users\Kotresh\AppData\Local\Programs\Python\Python36\lib\site-packages\flask\app.py", line 2292, in wsgi_app
    response = self.full_dispatch_request()
  File "C:\Users\Kotresh\AppData\Local\Programs\Python\Python36\lib\site-packages\flask\app.py", line 1815, in full_dispatch_request
    rv = self.handle_user_exception(e)
  File "C:\Users\Kotresh\AppData\Local\Programs\Python\Python36\lib\site-packages\flask_cors\extension.py", line 161, in wrapped_function
    return cors_after_request(app.make_response(f(*args, **kwargs)))
  File "C:\Users\Kotresh\AppData\Local\Programs\Python\Python36\lib\site-packages\flask\app.py", line 1718, in handle_user_exception
    reraise(exc_type, exc_value, tb)
  File "C:\Users\Kotresh\AppData\Local\Programs\Python\Python36\lib\site-packages\flask\_compat.py", line 35, in reraise
    raise value
  File "C:\Users\Kotresh\AppData\Local\Programs\Python\Python36\lib\site-packages\flask\app.py", line 1813, in full_dispatch_request
    rv = self.dispatch_request()
  File "C:\Users\Kotresh\AppData\Local\Programs\Python\Python36\lib\site-packages\flask\app.py", line 1799, in dispatch_request
    return self.view_functions[rule.endpoint](**req.view_args)
  File "api.py", line 77, in checkCounterfeit
    f = open(filepath,)
FileNotFoundError: [Errno 2] No such file or directory: '/results/counterfeit/HS_1.json'
Exception on /api/checkCounterfeit [GET]
Traceback (most recent call last):
  File "C:\Users\Kotresh\AppData\Local\Programs\Python\Python36\lib\site-packages\flask\app.py", line 2292, in wsgi_app
    response = self.full_dispatch_request()
  File "C:\Users\Kotresh\AppData\Local\Programs\Python\Python36\lib\site-packages\flask\app.py", line 1815, in full_dispatch_request
    rv = self.handle_user_exception(e)
  File "C:\Users\Kotresh\AppData\Local\Programs\Python\Python36\lib\site-packages\flask_cors\extension.py", line 161, in wrapped_function
    return cors_after_request(app.make_response(f(*args, **kwargs)))
  File "C:\Users\Kotresh\AppData\Local\Programs\Python\Python36\lib\site-packages\flask\app.py", line 1718, in handle_user_exception
    reraise(exc_type, exc_value, tb)
  File "C:\Users\Kotresh\AppData\Local\Programs\Python\Python36\lib\site-packages\flask\_compat.py", line 35, in reraise
    raise value
  File "C:\Users\Kotresh\AppData\Local\Programs\Python\Python36\lib\site-packages\flask\app.py", line 1813, in full_dispatch_request
    rv = self.dispatch_request()
  File "C:\Users\Kotresh\AppData\Local\Programs\Python\Python36\lib\site-packages\flask\app.py", line 1799, in dispatch_request
    return self.view_functions[rule.endpoint](**req.view_args)
  File "api.py", line 76, in checkCounterfeit
    filename = request.args.get('filename') + '.json'
FileNotFoundError: [Errno 2] No such file or directory: 'results/counterfeit/BigBazaar.json'
Exception on /api/checkCounterfeit [GET]
Traceback (most recent call last):
  File "C:\Users\Kotresh\AppData\Local\Programs\Python\Python36\lib\site-packages\flask\app.py", line 2292, in wsgi_app
    response = self.full_dispatch_request()
  File "C:\Users\Kotresh\AppData\Local\Programs\Python\Python36\lib\site-packages\flask\app.py", line 1815, in full_dispatch_request
    rv = self.handle_user_exception(e)
  File "C:\Users\Kotresh\AppData\Local\Programs\Python\Python36\lib\site-packages\flask_cors\extension.py", line 161, in wrapped_function
    return cors_after_request(app.make_response(f(*args, **kwargs)))
  File "C:\Users\Kotresh\AppData\Local\Programs\Python\Python36\lib\site-packages\flask\app.py", line 1718, in handle_user_exception
    reraise(exc_type, exc_value, tb)
  File "C:\Users\Kotresh\AppData\Local\Programs\Python\Python36\lib\site-packages\flask\_compat.py", line 35, in reraise
    raise value
  File "C:\Users\Kotresh\AppData\Local\Programs\Python\Python36\lib\site-packages\flask\app.py", line 1813, in full_dispatch_request
    rv = self.dispatch_request()
  File "C:\Users\Kotresh\AppData\Local\Programs\Python\Python36\lib\site-packages\flask\app.py", line 1799, in dispatch_request
    return self.view_functions[rule.endpoint](**req.view_args)
  File "api.py", line 78, in checkCounterfeit
    f = open(filepath,)
FileNotFoundError: [Errno 2] No such file or directory: 'results/counterfeit/BigBazaar.json'
Exception on /api/getEstimatedPos [GET]
Traceback (most recent call last):
  File "C:\Users\Kotresh\AppData\Local\Programs\Python\Python36\lib\site-packages\flask\app.py", line 2292, in wsgi_app
    response = self.full_dispatch_request()
  File "C:\Users\Kotresh\AppData\Local\Programs\Python\Python36\lib\site-packages\flask\app.py", line 1815, in full_dispatch_request
    rv = self.handle_user_exception(e)
  File "C:\Users\Kotresh\AppData\Local\Programs\Python\Python36\lib\site-packages\flask_cors\extension.py", line 161, in wrapped_function
    return cors_after_request(app.make_response(f(*args, **kwargs)))
  File "C:\Users\Kotresh\AppData\Local\Programs\Python\Python36\lib\site-packages\flask\app.py", line 1718, in handle_user_exception
    reraise(exc_type, exc_value, tb)
  File "C:\Users\Kotresh\AppData\Local\Programs\Python\Python36\lib\site-packages\flask\_compat.py", line 35, in reraise
    raise value
  File "C:\Users\Kotresh\AppData\Local\Programs\Python\Python36\lib\site-packages\flask\app.py", line 1813, in full_dispatch_request
    rv = self.dispatch_request()
  File "C:\Users\Kotresh\AppData\Local\Programs\Python\Python36\lib\site-packages\flask\app.py", line 1799, in dispatch_request
    return self.view_functions[rule.endpoint](**req.view_args)
  File "api.py", line 89, in getEstimatedPos
    filename = request.args.get('filename') + '.json'
TypeError: unsupported operand type(s) for +: 'NoneType' and 'str'
Exception on /api/getPosReportData [GET]
Traceback (most recent call last):
  File "C:\Users\Kotresh\AppData\Local\Programs\Python\Python36\lib\site-packages\flask\app.py", line 2292, in wsgi_app
    response = self.full_dispatch_request()
  File "C:\Users\Kotresh\AppData\Local\Programs\Python\Python36\lib\site-packages\flask\app.py", line 1815, in full_dispatch_request
    rv = self.handle_user_exception(e)
  File "C:\Users\Kotresh\AppData\Local\Programs\Python\Python36\lib\site-packages\flask_cors\extension.py", line 161, in wrapped_function
    return cors_after_request(app.make_response(f(*args, **kwargs)))
  File "C:\Users\Kotresh\AppData\Local\Programs\Python\Python36\lib\site-packages\flask\app.py", line 1718, in handle_user_exception
    reraise(exc_type, exc_value, tb)
  File "C:\Users\Kotresh\AppData\Local\Programs\Python\Python36\lib\site-packages\flask\_compat.py", line 35, in reraise
    raise value
  File "C:\Users\Kotresh\AppData\Local\Programs\Python\Python36\lib\site-packages\flask\app.py", line 1813, in full_dispatch_request
    rv = self.dispatch_request()
  File "C:\Users\Kotresh\AppData\Local\Programs\Python\Python36\lib\site-packages\flask\app.py", line 1799, in dispatch_request
    return self.view_functions[rule.endpoint](**req.view_args)
  File "api.py", line 86, in getPosReportData
    return jsonify(resp)
  File "C:\Users\Kotresh\AppData\Local\Programs\Python\Python36\lib\site-packages\flask\json\__init__.py", line 321, in jsonify
    dumps(data, indent=indent, separators=separators) + '\n',
  File "C:\Users\Kotresh\AppData\Local\Programs\Python\Python36\lib\site-packages\flask\json\__init__.py", line 179, in dumps
    rv = _json.dumps(obj, **kwargs)
  File "C:\Users\Kotresh\AppData\Local\Programs\Python\Python36\lib\json\__init__.py", line 238, in dumps
    **kw).encode(obj)
  File "C:\Users\Kotresh\AppData\Local\Programs\Python\Python36\lib\json\encoder.py", line 199, in encode
    chunks = self.iterencode(o, _one_shot=True)
  File "C:\Users\Kotresh\AppData\Local\Programs\Python\Python36\lib\json\encoder.py", line 257, in iterencode
    return _iterencode(o, 0)
  File "C:\Users\Kotresh\AppData\Local\Programs\Python\Python36\lib\site-packages\flask\json\__init__.py", line 81, in default
    return _json.JSONEncoder.default(self, o)
  File "C:\Users\Kotresh\AppData\Local\Programs\Python\Python36\lib\json\encoder.py", line 180, in default
    o.__class__.__name__)
TypeError: Object of type 'Series' is not JSON serializable
Exception on /api/getPosReportData [GET]
Traceback (most recent call last):
  File "C:\Users\Kotresh\AppData\Local\Programs\Python\Python36\lib\site-packages\flask\app.py", line 1974, in make_response
    rv = self.response_class.force_type(rv, request.environ)
  File "C:\Users\Kotresh\AppData\Local\Programs\Python\Python36\lib\site-packages\werkzeug\wrappers.py", line 921, in force_type
    response = BaseResponse(*_run_wsgi_app(response, environ))
  File "C:\Users\Kotresh\AppData\Local\Programs\Python\Python36\lib\site-packages\werkzeug\wrappers.py", line 59, in _run_wsgi_app
    return _run_wsgi_app(*args)
  File "C:\Users\Kotresh\AppData\Local\Programs\Python\Python36\lib\site-packages\werkzeug\test.py", line 923, in run_wsgi_app
    app_rv = app(environ, start_response)
TypeError: 'list' object is not callable

During handling of the above exception, another exception occurred:

Traceback (most recent call last):
  File "C:\Users\Kotresh\AppData\Local\Programs\Python\Python36\lib\site-packages\flask\app.py", line 2292, in wsgi_app
    response = self.full_dispatch_request()
  File "C:\Users\Kotresh\AppData\Local\Programs\Python\Python36\lib\site-packages\flask\app.py", line 1816, in full_dispatch_request
    return self.finalize_request(rv)
  File "C:\Users\Kotresh\AppData\Local\Programs\Python\Python36\lib\site-packages\flask\app.py", line 1831, in finalize_request
    response = self.make_response(rv)
  File "C:\Users\Kotresh\AppData\Local\Programs\Python\Python36\lib\site-packages\flask\app.py", line 1982, in make_response
    reraise(TypeError, new_error, sys.exc_info()[2])
  File "C:\Users\Kotresh\AppData\Local\Programs\Python\Python36\lib\site-packages\flask\_compat.py", line 34, in reraise
    raise value.with_traceback(tb)
  File "C:\Users\Kotresh\AppData\Local\Programs\Python\Python36\lib\site-packages\flask\app.py", line 1974, in make_response
    rv = self.response_class.force_type(rv, request.environ)
  File "C:\Users\Kotresh\AppData\Local\Programs\Python\Python36\lib\site-packages\werkzeug\wrappers.py", line 921, in force_type
    response = BaseResponse(*_run_wsgi_app(response, environ))
  File "C:\Users\Kotresh\AppData\Local\Programs\Python\Python36\lib\site-packages\werkzeug\wrappers.py", line 59, in _run_wsgi_app
    return _run_wsgi_app(*args)
  File "C:\Users\Kotresh\AppData\Local\Programs\Python\Python36\lib\site-packages\werkzeug\test.py", line 923, in run_wsgi_app
    app_rv = app(environ, start_response)
TypeError: 'list' object is not callable
The view function did not return a valid response. The return type must be a string, tuple, Response instance, or WSGI callable, but it was a list.
Exception on /api/getPosReportData [GET]
Traceback (most recent call last):
  File "C:\Users\Kotresh\AppData\Local\Programs\Python\Python36\lib\site-packages\flask\app.py", line 1974, in make_response
    rv = self.response_class.force_type(rv, request.environ)
  File "C:\Users\Kotresh\AppData\Local\Programs\Python\Python36\lib\site-packages\werkzeug\wrappers.py", line 921, in force_type
    response = BaseResponse(*_run_wsgi_app(response, environ))
  File "C:\Users\Kotresh\AppData\Local\Programs\Python\Python36\lib\site-packages\werkzeug\test.py", line 923, in run_wsgi_app
    app_rv = app(environ, start_response)
TypeError: 'list' object is not callable

During handling of the above exception, another exception occurred:

Traceback (most recent call last):
  File "C:\Users\Kotresh\AppData\Local\Programs\Python\Python36\lib\site-packages\flask\app.py", line 2292, in wsgi_app
    response = self.full_dispatch_request()
  File "C:\Users\Kotresh\AppData\Local\Programs\Python\Python36\lib\site-packages\flask\app.py", line 1816, in full_dispatch_request
    return self.finalize_request(rv)
  File "C:\Users\Kotresh\AppData\Local\Programs\Python\Python36\lib\site-packages\flask\app.py", line 1831, in finalize_request
    response = self.make_response(rv)
  File "C:\Users\Kotresh\AppData\Local\Programs\Python\Python36\lib\site-packages\flask\app.py", line 1982, in make_response
    reraise(TypeError, new_error, sys.exc_info()[2])
  File "C:\Users\Kotresh\AppData\Local\Programs\Python\Python36\lib\site-packages\flask\_compat.py", line 34, in reraise
    raise value.with_traceback(tb)
  File "C:\Users\Kotresh\AppData\Local\Programs\Python\Python36\lib\site-packages\flask\app.py", line 1974, in make_response
    rv = self.response_class.force_type(rv, request.environ)
  File "C:\Users\Kotresh\AppData\Local\Programs\Python\Python36\lib\site-packages\werkzeug\wrappers.py", line 921, in force_type
    response = BaseResponse(*_run_wsgi_app(response, environ))
  File "C:\Users\Kotresh\AppData\Local\Programs\Python\Python36\lib\site-packages\werkzeug\test.py", line 923, in run_wsgi_app
    app_rv = app(environ, start_response)
TypeError: 'list' object is not callable
The view function did not return a valid response. The return type must be a string, tuple, Response instance, or WSGI callable, but it was a list.
Exception on /api/getTrafficSummary [GET]
Traceback (most recent call last):
  File "C:\Users\Kotresh\AppData\Local\Programs\Python\Python36\lib\site-packages\flask\app.py", line 2292, in wsgi_app
    response = self.full_dispatch_request()
  File "C:\Users\Kotresh\AppData\Local\Programs\Python\Python36\lib\site-packages\flask\app.py", line 1815, in full_dispatch_request
    rv = self.handle_user_exception(e)
  File "C:\Users\Kotresh\AppData\Local\Programs\Python\Python36\lib\site-packages\flask_cors\extension.py", line 161, in wrapped_function
    return cors_after_request(app.make_response(f(*args, **kwargs)))
  File "C:\Users\Kotresh\AppData\Local\Programs\Python\Python36\lib\site-packages\flask\app.py", line 1718, in handle_user_exception
    reraise(exc_type, exc_value, tb)
  File "C:\Users\Kotresh\AppData\Local\Programs\Python\Python36\lib\site-packages\flask\_compat.py", line 35, in reraise
    raise value
  File "C:\Users\Kotresh\AppData\Local\Programs\Python\Python36\lib\site-packages\flask\app.py", line 1813, in full_dispatch_request
    rv = self.dispatch_request()
  File "C:\Users\Kotresh\AppData\Local\Programs\Python\Python36\lib\site-packages\flask\app.py", line 1799, in dispatch_request
    return self.view_functions[rule.endpoint](**req.view_args)
  File "api.py", line 42, in getTrafficSummary
    resp = csv_to_dictionary('results/traffic/Combined.csv')
  File "D:\P&G\GitHub\app-pgic\app-pgic-api\results\traffic\Convert_CSV_to_Dictionary.py", line 20, in csv_to_dictionary
    dictionary[c] = data[c].fillna(NaN, inplace = True).tolist()
NameError: name 'NaN' is not defined
Exception on /api/getTrafficSummary [GET]
Traceback (most recent call last):
  File "C:\Users\Kotresh\AppData\Local\Programs\Python\Python36\lib\site-packages\flask\app.py", line 2292, in wsgi_app
    response = self.full_dispatch_request()
  File "C:\Users\Kotresh\AppData\Local\Programs\Python\Python36\lib\site-packages\flask\app.py", line 1815, in full_dispatch_request
    rv = self.handle_user_exception(e)
  File "C:\Users\Kotresh\AppData\Local\Programs\Python\Python36\lib\site-packages\flask_cors\extension.py", line 161, in wrapped_function
    return cors_after_request(app.make_response(f(*args, **kwargs)))
  File "C:\Users\Kotresh\AppData\Local\Programs\Python\Python36\lib\site-packages\flask\app.py", line 1718, in handle_user_exception
    reraise(exc_type, exc_value, tb)
  File "C:\Users\Kotresh\AppData\Local\Programs\Python\Python36\lib\site-packages\flask\_compat.py", line 35, in reraise
    raise value
  File "C:\Users\Kotresh\AppData\Local\Programs\Python\Python36\lib\site-packages\flask\app.py", line 1813, in full_dispatch_request
    rv = self.dispatch_request()
  File "C:\Users\Kotresh\AppData\Local\Programs\Python\Python36\lib\site-packages\flask\app.py", line 1799, in dispatch_request
    return self.view_functions[rule.endpoint](**req.view_args)
  File "api.py", line 42, in getTrafficSummary
    resp = csv_to_dictionary('results/traffic/Combined.csv')
  File "D:\P&G\GitHub\app-pgic\app-pgic-api\results\traffic\Convert_CSV_to_Dictionary.py", line 20, in csv_to_dictionary
    dictionary[c] = data[c].fillna("-", inplace = True).tolist()
AttributeError: 'NoneType' object has no attribute 'tolist'
Exception on /api/getPosReportData [GET]
Traceback (most recent call last):
  File "C:\Python27\lib\site-packages\flask\app.py", line 2447, in wsgi_app
    response = self.full_dispatch_request()
  File "C:\Python27\lib\site-packages\flask\app.py", line 1952, in full_dispatch_request
    rv = self.handle_user_exception(e)
  File "C:\Python27\lib\site-packages\flask_cors\extension.py", line 161, in wrapped_function
    return cors_after_request(app.make_response(f(*args, **kwargs)))
  File "C:\Python27\lib\site-packages\flask\app.py", line 1821, in handle_user_exception
    reraise(exc_type, exc_value, tb)
  File "C:\Python27\lib\site-packages\flask\app.py", line 1950, in full_dispatch_request
    rv = self.dispatch_request()
  File "C:\Python27\lib\site-packages\flask\app.py", line 1936, in dispatch_request
    return self.view_functions[rule.endpoint](**req.view_args)
  File "api.py", line 89, in getPosReportData
    Reads the json file with the specified file name and filters the data for the specified parameter values.
  File "results/pos_reports\WarehouseStorage.py", line 18, in show_details
    data = pd.read_excel(filepath)
  File "C:\Python27\lib\site-packages\pandas\util\_decorators.py", line 188, in wrapper
    return func(*args, **kwargs)
  File "C:\Python27\lib\site-packages\pandas\util\_decorators.py", line 188, in wrapper
    return func(*args, **kwargs)
  File "C:\Python27\lib\site-packages\pandas\io\excel.py", line 350, in read_excel
    io = ExcelFile(io, engine=engine)
  File "C:\Python27\lib\site-packages\pandas\io\excel.py", line 653, in __init__
    self._reader = self._engines[engine](self._io)
  File "C:\Python27\lib\site-packages\pandas\io\excel.py", line 393, in __init__
    raise ImportError(err_msg)
ImportError: Install xlrd >= 1.0.0 for Excel support
Exception on /api/getPosReportData [GET]
Traceback (most recent call last):
  File "C:\Python27\lib\site-packages\flask\app.py", line 2447, in wsgi_app
    response = self.full_dispatch_request()
  File "C:\Python27\lib\site-packages\flask\app.py", line 1952, in full_dispatch_request
    rv = self.handle_user_exception(e)
  File "C:\Python27\lib\site-packages\flask_cors\extension.py", line 161, in wrapped_function
    return cors_after_request(app.make_response(f(*args, **kwargs)))
  File "C:\Python27\lib\site-packages\flask\app.py", line 1821, in handle_user_exception
    reraise(exc_type, exc_value, tb)
  File "C:\Python27\lib\site-packages\flask\app.py", line 1950, in full_dispatch_request
    rv = self.dispatch_request()
  File "C:\Python27\lib\site-packages\flask\app.py", line 1936, in dispatch_request
    return self.view_functions[rule.endpoint](**req.view_args)
  File "api.py", line 89, in getPosReportData
    Reads the json file with the specified file name and filters the data for the specified parameter values.
  File "results/pos_reports\WarehouseStorage.py", line 18, in show_details
    data = pd.read_excel(filepath)
  File "C:\Python27\lib\site-packages\pandas\util\_decorators.py", line 188, in wrapper
    return func(*args, **kwargs)
  File "C:\Python27\lib\site-packages\pandas\util\_decorators.py", line 188, in wrapper
    return func(*args, **kwargs)
  File "C:\Python27\lib\site-packages\pandas\io\excel.py", line 350, in read_excel
    io = ExcelFile(io, engine=engine)
  File "C:\Python27\lib\site-packages\pandas\io\excel.py", line 653, in __init__
    self._reader = self._engines[engine](self._io)
  File "C:\Python27\lib\site-packages\pandas\io\excel.py", line 393, in __init__
    raise ImportError(err_msg)
ImportError: Install xlrd >= 1.0.0 for Excel support
Exception on /api/getPosReportData [GET]
Traceback (most recent call last):
  File "C:\Python27\lib\site-packages\flask\app.py", line 2447, in wsgi_app
    response = self.full_dispatch_request()
  File "C:\Python27\lib\site-packages\flask\app.py", line 1952, in full_dispatch_request
    rv = self.handle_user_exception(e)
  File "C:\Python27\lib\site-packages\flask_cors\extension.py", line 161, in wrapped_function
    return cors_after_request(app.make_response(f(*args, **kwargs)))
  File "C:\Python27\lib\site-packages\flask\app.py", line 1821, in handle_user_exception
    reraise(exc_type, exc_value, tb)
  File "C:\Python27\lib\site-packages\flask\app.py", line 1950, in full_dispatch_request
    rv = self.dispatch_request()
  File "C:\Python27\lib\site-packages\flask\app.py", line 1936, in dispatch_request
    return self.view_functions[rule.endpoint](**req.view_args)
  File "api.py", line 89, in getPosReportData
    Reads the json file with the specified file name and filters the data for the specified parameter values.
  File "results/pos_reports\WarehouseStorage.py", line 18, in show_details
    data = pd.read_excel(filepath)
  File "C:\Python27\lib\site-packages\pandas\util\_decorators.py", line 188, in wrapper
    return func(*args, **kwargs)
  File "C:\Python27\lib\site-packages\pandas\util\_decorators.py", line 188, in wrapper
    return func(*args, **kwargs)
  File "C:\Python27\lib\site-packages\pandas\io\excel.py", line 350, in read_excel
    io = ExcelFile(io, engine=engine)
  File "C:\Python27\lib\site-packages\pandas\io\excel.py", line 653, in __init__
    self._reader = self._engines[engine](self._io)
  File "C:\Python27\lib\site-packages\pandas\io\excel.py", line 393, in __init__
    raise ImportError(err_msg)
ImportError: Install xlrd >= 1.0.0 for Excel support
Exception on /api/getPosReportData [GET]
Traceback (most recent call last):
  File "C:\Users\Kotresh\AppData\Local\Programs\Python\Python36\lib\site-packages\flask\app.py", line 2292, in wsgi_app
    response = self.full_dispatch_request()
  File "C:\Users\Kotresh\AppData\Local\Programs\Python\Python36\lib\site-packages\flask\app.py", line 1815, in full_dispatch_request
    rv = self.handle_user_exception(e)
  File "C:\Users\Kotresh\AppData\Local\Programs\Python\Python36\lib\site-packages\flask_cors\extension.py", line 161, in wrapped_function
    return cors_after_request(app.make_response(f(*args, **kwargs)))
  File "C:\Users\Kotresh\AppData\Local\Programs\Python\Python36\lib\site-packages\flask\app.py", line 1718, in handle_user_exception
    reraise(exc_type, exc_value, tb)
  File "C:\Users\Kotresh\AppData\Local\Programs\Python\Python36\lib\site-packages\flask\_compat.py", line 35, in reraise
    raise value
  File "C:\Users\Kotresh\AppData\Local\Programs\Python\Python36\lib\site-packages\flask\app.py", line 1813, in full_dispatch_request
    rv = self.dispatch_request()
  File "C:\Users\Kotresh\AppData\Local\Programs\Python\Python36\lib\site-packages\flask\app.py", line 1799, in dispatch_request
    return self.view_functions[rule.endpoint](**req.view_args)
  File "api.py", line 99, in getPosReportData
    resp = show_details(fromdate, todate, state, city, product, filepath)
  File "results/pos_reports\WarehouseStorage.py", line 34, in show_details
    if(len(value) == 0 and index == 'input_start_date'):
TypeError: object of type 'NoneType' has no len()
Exception on /api/getPosReportData [GET]
Traceback (most recent call last):
  File "C:\Users\Kotresh\AppData\Local\Programs\Python\Python36\lib\site-packages\flask\app.py", line 2292, in wsgi_app
    response = self.full_dispatch_request()
  File "C:\Users\Kotresh\AppData\Local\Programs\Python\Python36\lib\site-packages\flask\app.py", line 1815, in full_dispatch_request
    rv = self.handle_user_exception(e)
  File "C:\Users\Kotresh\AppData\Local\Programs\Python\Python36\lib\site-packages\flask_cors\extension.py", line 161, in wrapped_function
    return cors_after_request(app.make_response(f(*args, **kwargs)))
  File "C:\Users\Kotresh\AppData\Local\Programs\Python\Python36\lib\site-packages\flask\app.py", line 1718, in handle_user_exception
    reraise(exc_type, exc_value, tb)
  File "C:\Users\Kotresh\AppData\Local\Programs\Python\Python36\lib\site-packages\flask\_compat.py", line 35, in reraise
    raise value
  File "C:\Users\Kotresh\AppData\Local\Programs\Python\Python36\lib\site-packages\flask\app.py", line 1813, in full_dispatch_request
    rv = self.dispatch_request()
  File "C:\Users\Kotresh\AppData\Local\Programs\Python\Python36\lib\site-packages\flask\app.py", line 1799, in dispatch_request
    return self.view_functions[rule.endpoint](**req.view_args)
  File "api.py", line 99, in getPosReportData
    resp = show_details(fromdate, todate, state, city, product, filepath)
  File "results/pos_reports\WarehouseStorage.py", line 27, in show_details
    if(len(value) == 0):
TypeError: object of type 'NoneType' has no len()
